Unable to init server: Could not connect: Connection refused
Unable to init server: Could not connect: Connection refused

(parallel_analysis.py:3963583): Gdk-CRITICAL **: 15:24:57.445: gdk_cursor_new_for_display: assertion 'GDK_IS_DISPLAY (display)' failed
/space/ge83qez/DymerKrylov/dimers_util.py:182: FutureWarning: in the future insert will treat boolean arrays and array-likes as boolean index instead of casting it to integer
  h_hops = np.delete(hops, np.any(hops <= 2, axis=1), axis=0)
Process Process-2:
multiprocessing.pool.RemoteTraceback: 
"""
Traceback (most recent call last):
  File "/usr/lib/python3.8/multiprocessing/pool.py", line 125, in worker
    result = (True, func(*args, **kwds))
  File "/usr/lib/python3.8/multiprocessing/pool.py", line 48, in mapstar
    return list(map(*args))
  File "/space/ge83qez/DymerKrylov/dimers_sim.py", line 175, in classical_evolutions_batch
    for i in self.progress_bar(range(self.times)):
  File "/space/ge83qez/DymerKrylov/dimers_sim.py", line 90, in progress_bar
    return tqdm(iterable, miniters= self.times//25, desc=tqdm_text, position=0, leave=False)
NameError: name 'tqdm' is not defined
"""

The above exception was the direct cause of the following exception:

Traceback (most recent call last):
  File "/usr/lib/python3.8/multiprocessing/process.py", line 315, in _bootstrap
    self.run()
  File "/usr/lib/python3.8/multiprocessing/process.py", line 108, in run
    self._target(*self._args, **self._kwargs)
  File "/space/ge83qez/DymerKrylov/dimers_sim.py", line 130, in simulate_parallel_task
    q.put(sim.simulate())
  File "/space/ge83qez/DymerKrylov/dimers_sim.py", line 140, in simulate
    c_rhos =  p.map(self.classical_evolutions_batch, (H for i in range(self.batch_procs_num)), chunksize=1)
  File "/usr/lib/python3.8/multiprocessing/pool.py", line 364, in map
    return self._map_async(func, iterable, mapstar, chunksize).get()
  File "/usr/lib/python3.8/multiprocessing/pool.py", line 771, in get
    raise self._value
NameError: name 'tqdm' is not defined
No handles with labels found to put in legend.
Unable to init server: Could not connect: Connection refused
Unable to init server: Could not connect: Connection refused

(parallel_analysis.py:3963866): Gdk-CRITICAL **: 15:25:42.479: gdk_cursor_new_for_display: assertion 'GDK_IS_DISPLAY (display)' failed
/space/ge83qez/DymerKrylov/dimers_util.py:182: FutureWarning: in the future insert will treat boolean arrays and array-likes as boolean index instead of casting it to integer
  h_hops = np.delete(hops, np.any(hops <= 2, axis=1), axis=0)
